Workbook

Sheet Summary
B2: ANONA / TENET
B3: Seed Round Investment Plan
B4: Prepared for investor + legal review | May 2026 | Notes & comparables refreshed June 2026 (no inputs changed)
B6: ROUND OVERVIEW
B7: Round | C7: Seed
B8: Target raise | C8: 3750000 | F8: Primary target
B9: Floor | C9: 3500000 | F9: Executes plan on tighter ~16-mo runway
B10: Ceiling | C10: 4500000 | F10: Oversubscribed; extends toward 22 mo
B11: Runway target | C11: 18–22 months | F11: To credible Series A
B12: Instrument | C12: TBD — see Funding Mechanism tab | F12: Bridge vs. accelerated first close
B15: USE OF FUNDS — $3.75M TARGET | C15: Allocation | D15: % of Raise
B16: Engineering & infrastructure | C16: 1800000 | D16: =C16/$C$21 -> 0.48
B17: Design & product | C17: 400000 | D17: =C17/$C$21 -> 0.10666667
B18: Founder & operations | C18: 735000 | D18: =C18/$C$21 -> 0.196
B19: Brand & strategy | C19: 396000 | D19: =C19/$C$21 -> 0.1056 | F19: Brand build + strategy; thesis post-close
B20: Reserves / contingency | C20: 419000 | D20: =C20/$C$21 -> 0.11173333 | F20: ~11% buffer to extend runway
B21: Total | C21: =SUM(C16:C20) -> 3750000 | D21: =C21/$C$21 -> 1
B25: IMMEDIATE CAPITAL ASK (BRIDGE — FIRST 90 DAYS)
B26: Roger Obando — fractional CTO retainer | C26: =14000*3 -> 42000 | F26: $14K/mo × 3 months (bridge window)
B27: Immediate operating costs (legal, setup, infra) | C27: 24000 | F27: Estimate — refine on call
B28: Immediate ask total | C28: =SUM(C26:C27) -> 66000 | F28: Bridge only: Roger + legal/setup. Operating plan funded by seed.

Sheet Use of Funds
B2: Use of Funds — Detail
B3: Line-item breakdown supporting the $3.75M allocation
B5: Category / line item | C5: Amount | D5: % of Raise | E5: Notes
B6: ENGINEERING & INFRASTRUCTURE
B7: Engineering Lead (senior, AI orchestration) | C7: 320000 | D7: =C7/$C$41 -> 0.085333333 | E7: Top hire priority — fully loaded yr1
B8: Senior Frontend / Product Engineer (NLE-adjacent) | C8: 260000 | D8: =C8/$C$41 -> 0.069333333 | E8: Loaded yr1
B9: Second engineer (from month 4–5) | C9: 200000 | D9: =C9/$C$41 -> 0.053333333 | E9: Partial-year
B10: Cloud / GPU / model inference infra | C10: 480000 | D10: =C10/$C$41 -> 0.128 | E10: Generation + orchestration compute
B11: Tooling, licenses, dev infrastructure | C11: 140000 | D11: =C11/$C$41 -> 0.037333333
B12: Fractional CTO / eng-lead seat (5 mo + held) | C12: 70000 | D12: =C12/$C$41 -> 0.018666667 | E12: Roger M1–5; hands off to full-time Eng Lead (recruit from month 3)
B13: Engineering contingency | C13: 330000 | D13: =C13/$C$41 -> 0.088 | E13: Within engineering envelope
B14: Subtotal | C14: =SUM(C7:C13) -> 1800000 | D14: =C14/$C$41 -> 0.48
B16: DESIGN & PRODUCT
B17: Product Designer (multi-state UI / motion) | C17: 280000 | D17: =C17/$C$41 -> 0.074666667 | E17: Loaded yr1
B18: Design tooling & prototyping | C18: 40000 | D18: =C18/$C$41 -> 0.010666667
B19: Product validation (test sessions, instrumentation) | C19: 80000 | D19: =C19/$C$41 -> 0.021333333 | E19: ANONA-run; JANE provides live jobs as anchor customer
B20: Subtotal | C20: =SUM(C17:C19) -> 400000 | D20: =C20/$C$41 -> 0.10666667
B22: FOUNDER & OPERATIONS
B23: Founder compensation | C23: 390000 | D23: =C23/$C$41 -> 0.104 | E23: $20K/mo M1–3, $30K/mo M4–18
B24: Legal, accounting, corporate formation | C24: 70000 | D24: =C24/$C$41 -> 0.018666667 | E24: Incl. round + ongoing counsel
B25: Producer / Operations (full-time, day 15) | C25: 225000 | D25: =C25/$C$41 -> 0.06 | E25: $225K/yr loaded, full-time from day 15
B26: Office / operations / misc. | C26: 50000 | D26: =C26/$C$41 -> 0.013333333
B27: Subtotal | C27: =SUM(C23:C26) -> 735000 | D27: =C27/$C$41 -> 0.196
B29: BRAND & STRATEGY
B30: Strategy (positioning, GTM, advisory team) | C30: 280000 | D30: =C30/$C$41 -> 0.074666667 | E30: Team supporting founder from day 15
B31: Brand development (website, identity, system) | C31: 116000 | D31: =C31/$C$41 -> 0.030933333 | E31: Site, logo, design system; starts month 3
B32: Subtotal | C32: =SUM(C30:C31) -> 396000 | D32: =C32/$C$41 -> 0.1056
B34: RESERVES / CONTINGENCY
B35: Unallocated reserve | C35: 419000 | D35: =C35/$C$41 -> 0.11173333 | E35: ~11% buffer to extend runway
B36: Subtotal | C36: =SUM(C35:C35) -> 419000 | D36: =C36/$C$41 -> 0.11173333
B41: TOTAL RAISE | C41: =C14+C20+C27+C32+C36 -> 3750000 | D41: =C41/C41 -> 1
B43: Salary figures are fully-loaded yr1 estimates (incl. benefits/taxes). Headcount per Section 7 hiring plan.

Sheet Funding Mechanism
B2: Funding Mechanism — Our Recommendation
B3: How we propose to fund the first 60–90 days while the full seed closes
C5: Option 1 — Bridge / Convertible Note | D5: Option 2 — Accelerated First Close
B6: What it is | C6: Short-term note covering immediate operating expenses; converts into the seed round at close. | D6: Pull a tranche of the seed forward to fund first 90 days; balance closes on normal timeline.
B7: Covers | C7: Covers Roger and immediate operating costs through close. | D7: Covers Roger plus first-90-day operations against the priced round.
B8: Speed to deploy | C8: Fast — note docs are lighter than full round close. | D8: Depends on first-close readiness; can be quick if leads are committed.
B9: Legal lift | C9: Lower upfront; note + cap/discount terms. | D9: Higher — requires priced/structured round docs sooner.
B10: Dilution clarity | C10: Deferred — converts later at cap/discount. | D10: Immediate — priced at close.
B11: Best when | C11: We use this to preserve momentum without locking full round terms before close. | D11: We use this when leads are ready to commit and prefer a single clean instrument.
B12: Why it fits here | C12: Fastest way to get the team operational and the build moving immediately. | D12: Cleanest cap-table outcome if the round prices on the near-term timeline.
B14: RECOMMENDED PATH
B15: We recommend a HYBRID: a short-term bridge note funds the first 90 days (Roger + legal/setup, ~$66K), then converts into the priced seed at the round close. This protects the start date without locking full round terms early. Note terms (cap, discount, conversion trigger) to be finalized with counsel — see below.
B17: BRIDGE SCOPE
B18: The bridge funds only Roger’s engagement (3 months) and legal/corporate setup (~$66K) during the 90-day window while the full seed closes. It does NOT fund the 18-month operating plan, team buildout, or infrastructure — those are funded by the seed itself.
B20: HYBRID TERMS (to finalize with counsel)
B21: Bridge amount | C21: ~$66K (Roger 3 mo + legal/setup)
B22: Instrument | C22: Convertible note — TBD
B23: Conversion cap / discount | C23: TBD with counsel
B24: Conversion trigger | C24: Close of priced seed — TBD
B25: Exclusivity / timeline | C25: TBD with counsel

Sheet Runway
B2: 18-Month Runway — Illustrative Burn
B3: Simplified monthly view. Hiring ramps per Section 7. Refine on weekend call.
B5: ($ per month) | C5: M1 | D5: M2 | E5: M3 | F5: M4 | G5: M5 | H5: M6 | I5: M7 | J5: M8 | K5: M9 | L5: M10 | M5: M11 | N5: M12 | O5: M13 | P5: M14 | Q5: M15 | R5: M16 | S5: M17 | T5: M18
B6: Founder | C6: 20000 | D6: 20000 | E6: 20000 | F6: 30000 | G6: 30000 | H6: 30000 | I6: 30000 | J6: 30000 | K6: 30000 | L6: 30000 | M6: 30000 | N6: 30000 | O6: 30000 | P6: 30000 | Q6: 30000 | R6: 30000 | S6: 30000 | T6: 30000
B7: Producer / Operations | C7: 18750 | D7: 18750 | E7: 18750 | F7: 18750 | G7: 18750 | H7: 18750 | I7: 18750 | J7: 18750 | K7: 18750 | L7: 18750 | M7: 18750 | N7: 18750 | O7: 18750 | P7: 18750 | Q7: 18750 | R7: 18750 | S7: 18750 | T7: 18750
B8: Eng Lead | C8: 26667 | D8: 26667 | E8: 26667 | F8: 26667 | G8: 26667 | H8: 26667 | I8: 26667 | J8: 26667 | K8: 26667 | L8: 26667 | M8: 26667 | N8: 26667 | O8: 26667 | P8: 26667 | Q8: 26667 | R8: 26667 | S8: 26667 | T8: 26667
B9: Sr Frontend Eng | C9: 21667 | D9: 21667 | E9: 21667 | F9: 21667 | G9: 21667 | H9: 21667 | I9: 21667 | J9: 21667 | K9: 21667 | L9: 21667 | M9: 21667 | N9: 21667 | O9: 21667 | P9: 21667 | Q9: 21667 | R9: 21667 | S9: 21667 | T9: 21667
B10: Second Eng | C10: 0 | D10: 0 | E10: 0 | F10: 16667 | G10: 16667 | H10: 16667 | I10: 16667 | J10: 16667 | K10: 16667 | L10: 16667 | M10: 16667 | N10: 16667 | O10: 16667 | P10: 16667 | Q10: 16667 | R10: 16667 | S10: 16667 | T10: 16667
B11: Product Designer | C11: 23333 | D11: 23333 | E11: 23333 | F11: 23333 | G11: 23333 | H11: 23333 | I11: 23333 | J11: 23333 | K11: 23333 | L11: 23333 | M11: 23333 | N11: 23333 | O11: 23333 | P11: 23333 | Q11: 23333 | R11: 23333 | S11: 23333 | T11: 23333
B12: Eng-lead seat (Roger M1–5, then held) | C12: 14000 | D12: 14000 | E12: 14000 | F12: 14000 | G12: 14000 | H12: 14000 | I12: 14000 | J12: 14000 | K12: 14000 | L12: 14000 | M12: 14000 | N12: 14000 | O12: 14000 | P12: 14000 | Q12: 14000 | R12: 14000 | S12: 14000 | T12: 14000
B13: Infra / compute / tooling | C13: 34000 | D13: 34000 | E13: 34000 | F13: 34000 | G13: 34000 | H13: 34000 | I13: 34000 | J13: 34000 | K13: 34000 | L13: 34000 | M13: 34000 | N13: 34000 | O13: 34000 | P13: 34000 | Q13: 34000 | R13: 34000 | S13: 34000 | T13: 34000
B14: Brand & strategy | C14: 0 | D14: 0 | E14: 8000 | F14: 8000 | G14: 14000 | H14: 14000 | I14: 14000 | J14: 19000 | K14: 19000 | L14: 19000 | M14: 19000 | N14: 19000 | O14: 19000 | P14: 19000 | Q14: 19000 | R14: 19000 | S14: 19000 | T14: 19000
B16: Legal / ops / misc | C16: 8000 | D16: 8000 | E16: 8000 | F16: 14000 | G16: 14000 | H16: 14000 | I16: 14000 | J16: 14000 | K16: 14000 | L16: 9000 | M16: 9000 | N16: 9000 | O16: 9000 | P16: 9000 | Q16: 9000 | R16: 9000 | S16: 9000 | T16: 9000
B17: Monthly burn | C17: =SUM(C6:C16) -> 166417 | D17: =SUM(D6:D16) -> 166417 | E17: =SUM(E6:E16) -> 174417 | F17: =SUM(F6:F16) -> 207084 | G17: =SUM(G6:G16) -> 213084 | H17: =SUM(H6:H16) -> 213084 | I17: =SUM(I6:I16) -> 213084 | J17: =SUM(J6:J16) -> 218084 | ... T17: =SUM(T6:T16) -> 213084
B18: Capital remaining | C18: =3750000-C17 -> 3583583 | D18: =C18-D17 -> 3417166 | E18: =D18-E17 -> 3242749 | F18: =E18-F17 -> 3035665 | G18: =F18-G17 -> 2822581 | H18: =G18-H17 -> 2609497 | I18: =H18-I17 -> 2396413 | J18: =I18-J17 -> 2178329 | K18: =J18-K17 -> 1960245 | ... T18: =S18-T17 -> 42489
B21: Blue = input assumptions. Adjust monthly figures to model scenarios. Capital remaining stays positive across 18 months at $3.75M raise.

Sheet Pricing Assumptions
B2: ANONA / TENET
B3: Revenue Assumptions — inputs in blue
B4: Edit the blue cells to model scenarios. Everything on Revenue Ramp & Return Math flows from here.
B6: PRICING | C6: Value | D6: Source / note
B7: Anchor / enterprise account ACV ($/month) | C7: 20000 | D7: INPUT — JANE-type studio contract. Verify vs. actual JANE terms.
B8: Self-serve seat price ($/month) | C8: 79 | D8: INPUT — priced as production-grade. Benchmark: Magnific (ex-Freepik) individual tiers, repriced 2026 post-rebrand (Business plan launched early 2026); $79 sits above entry self-serve. Source: Magnific/Fortune, 2026.
B9: Usage / credits uplift (% of subscription) | C9: 0.25 | D9: INPUT — add-on compute/credits, like Magnific's token model (~$0.32/image).
B11: RETURN ASSUMPTIONS
B12: Seed raise ($) | C12: 3750000 | D12: From Summary tab — target round.
B13: Post-money valuation ($) | C13: 19000000 | D13: INPUT — base case at market-standard ~20% dilution (AI-seed median, per Valuation Basis). Supported by four funded categories now entering the coordination layer (see Comparable Companies). $15M is the conservative downside.
B14: Ownership retained through dilution (%) | C14: 0.55 | D14: INPUT — fraction of seed stake kept after future rounds to exit.
B15: Valuation multiple — conservative (x ARR) | C15: 8 | D15: INPUT — low end for creative-AI / vertical SaaS.
B16: Valuation multiple — base (x ARR) | C16: 15 | D16: INPUT — mid-teens. Frontier-model comp ElevenLabs ~22x ($11B / ~$500M ARR, Feb 2026); soberer coordination-layer comp Wrapbook ~$750M val on ~50% growth. Our 15x sits between. Source: TechCrunch / Hollywood Reporter, 2026.
B17: Valuation multiple — upside (x ARR) | C17: 22 | D17: INPUT — high end for fast-growing creative-AI infra.

Sheet Revenue Ramp
B2: ANONA / TENET
B3: 18-Month Revenue Ramp — illustrative
B4: Enterprise-led, JANE-anchored. Counts in blue are inputs; revenue lines are formulas off Pricing Assumptions. Gross burn links live to the Runway tab.
B6: ($ per month) | C6: M1 | D6: M2 | E6: M3 | F6: M4 | G6: M5 | H6: M6 | I6: M7 | J6: M8 | K6: M9 | L6: M10 | M6: M11 | N6: M12 | O6: M13 | P6: M14 | Q6: M15 | R6: M16 | S6: M17 | T6: M18
B7: Anchor / enterprise accounts (#) | C7: 0 | D7: 0 | E7: 0 | F7: 0 | G7: 0 | H7: 0 | I7: 1 | J7: 1 | K7: 2 | L7: 3 | M7: 4 | N7: 5 | O7: 6 | P7: 7 | Q7: 8 | R7: 9 | S7: 10 | T7: 12
B8: Self-serve seats (#) | C8: 0 | D8: 0 | E8: 0 | F8: 0 | G8: 0 | H8: 0 | I8: 0 | J8: 0 | K8: 25 | L8: 60 | M8: 120 | N8: 200 | O8: 320 | P8: 480 | Q8: 680 | R8: 920 | S8: 1200 | T8: 1500
B9: Anchor MRR | C9: =C7*'Pricing Assumptions'!$C$7 -> 0 | D9: =D7*'Pricing Assumptions'!$C$7 -> 0 | E9: =E7*'Pricing Assumptions'!$C$7 -> 0 | F9: =F7*'Pricing Assumptions'!$C$7 -> 0 | G9: =G7*'Pricing Assumptions'!$C$7 -> 0 | H9: =H7*'Pricing Assumptions'!$C$7 -> 0 | I9: =I7*'Pricing Assumptions'!$C$7 -> 20000 | J9: =J7*'Pricing Assumptions'!$C$7 -> 20000 | ... T9: =T7*'Pricing Assumptions'!$C$7 -> 240000
B10: Self-serve subscription MRR | C10: =C8*'Pricing Assumptions'!$C$8 -> 0 | D10: =D8*'Pricing Assumptions'!$C$8 -> 0 | E10: =E8*'Pricing Assumptions'!$C$8 -> 0 | F10: =F8*'Pricing Assumptions'!$C$8 -> 0 | G10: =G8*'Pricing Assumptions'!$C$8 -> 0 | H10: =H8*'Pricing Assumptions'!$C$8 -> 0 | I10: =I8*'Pricing Assumptions'!$C$8 -> 0 | J10: =J8*'Pricing Assumptions'!$C$8 -> 0 | ... T10: =T8*'Pricing Assumptions'!$C$8 -> 118500
B11: Usage / credits MRR | C11: =(C9+C10)*'Pricing Assumptions'!$C$9 -> 0 | D11: =(D9+D10)*'Pricing Assumptions'!$C$9 -> 0 | E11: =(E9+E10)*'Pricing Assumptions'!$C$9 -> 0 | F11: =(F9+F10)*'Pricing Assumptions'!$C$9 -> 0 | G11: =(G9+G10)*'Pricing Assumptions'!$C$9 -> 0 | H11: =(H9+H10)*'Pricing Assumptions'!$C$9 -> 0 | I11: =(I9+I10)*'Pricing Assumptions'!$C$9 -> 5000 | J11: =(J9+J10)*'Pricing Assumptions'!$C$9 -> 5000 | ... T11: =(T9+T10)*'Pricing Assumptions'!$C$9 -> 89625
B12: Total MRR | C12: =C9+C10+C11 -> 0 | D12: =D9+D10+D11 -> 0 | E12: =E9+E10+E11 -> 0 | F12: =F9+F10+F11 -> 0 | G12: =G9+G10+G11 -> 0 | H12: =H9+H10+H11 -> 0 | I12: =I9+I10+I11 -> 25000 | J12: =J9+J10+J11 -> 25000 | ... T12: =T9+T10+T11 -> 448125
B13: Revenue (monthly) | C13: =C12 -> 0 | D13: =D12 -> 0 | E13: =E12 -> 0 | F13: =F12 -> 0 | G13: =G12 -> 0 | H13: =H12 -> 0 | I13: =I12 -> 25000 | J13: =J12 -> 25000 | ... T13: =T12 -> 448125
B14: Gross burn (Runway tab) | C14: =Runway!C17 -> 166417 | D14: =Runway!D17 -> 166417 | E14: =Runway!E17 -> 174417 | F14: =Runway!F17 -> 207084 | G14: =Runway!G17 -> 213084 | H14: =Runway!H17 -> 213084 | I14: =Runway!I17 -> 213084 | J14: =Runway!J17 -> 218084 | ... T14: =Runway!T17 -> 213084
B15: Net burn (burn − revenue) | C15: =C14-C13 -> 166417 | D15: =D14-D13 -> 166417 | E15: =E14-E13 -> 174417 | F15: =F14-F13 -> 207084 | G15: =G14-G13 -> 213084 | H15: =H14-H13 -> 213084 | I15: =I14-I13 -> 188084 | J15: =J14-J13 -> 193084 | ... T15: =T14-T13 -> -235041
B17: HEADLINE
B18: Exit-rate ARR (Month 18 MRR × 12) | C18: =T12*12 -> 5377500
B19: Cumulative revenue (18 mo) | C19: =SUM(C13:T13) -> 2243618.8
B20: Total gross burn (18 mo) | C20: =SUM(C14:T14) -> 3707511
B21: Revenue offset to burn | C21: =C19/C20 -> 0.60515498
B22: First revenue month | C22: ="Month "&MATCH(TRUE(),INDEX(C13:T13>0,0),0) -> Month 7

Sheet Return Math
B2: ANONA / TENET
B3: Return Math — what it takes to return your capital
B4: Think of it as a development pro forma: capital in → build the asset → asset has an exit value (ARR × multiple) → your return = stake value ÷ capital in.
B6: OWNERSHIP
B7: Seed raise | C7: ='Pricing Assumptions'!$C$12 -> 3750000
B8: Post-money valuation | C8: ='Pricing Assumptions'!$C$13 -> 19000000
B9: Seed ownership at close | C9: =C7/C8 -> 0.19736842
B10: Ownership retained to exit | C10: ='Pricing Assumptions'!$C$14 -> 0.55
B11: Effective ownership at exit | C11: =C9*C10 -> 0.10855263
B14: INVESTOR RETURN (MOIC) — exit ARR × valuation multiple
C15: Conservative | D15: Base (from ramp) | E15: Upside
B16: Exit ARR → | C16: 3000000 | D16: ='Revenue Ramp'!$C$18 -> 5377500 | E16: 10000000 | F16: Multiple ↓
B17: Conservative multiple | C17: =C$16*$F17*$C$11/$C$7 -> 0.69473684 | D17: =D$16*$F17*$C$11/$C$7 -> 1.2453158 | E17: =E$16*$F17*$C$11/$C$7 -> 2.3157895 | F17: ='Pricing Assumptions'!$C$15 -> 8
B18: Base multiple | C18: =C$16*$F18*$C$11/$C$7 -> 1.3026316 | D18: =D$16*$F18*$C$11/$C$7 -> 2.3349671 | E18: =E$16*$F18*$C$11/$C$7 -> 4.3421053 | F18: ='Pricing Assumptions'!$C$16 -> 15
B19: Upside multiple | C19: =C$16*$F19*$C$11/$C$7 -> 1.9105263 | D19: =D$16*$F19*$C$11/$C$7 -> 3.4246184 | E19: =E$16*$F19*$C$11/$C$7 -> 6.3684211 | F19: ='Pricing Assumptions'!$C$17 -> 22
B22: WHAT ARR DO WE NEED — at base multiple
B23: ARR needed to return 1.0x (capital back) | C23: =(1*C7)/(C11*'Pricing Assumptions'!$C$16) -> 2303030.3
B24: ARR needed to return 3.0x | C24: =(3*C7)/(C11*'Pricing Assumptions'!$C$16) -> 6909090.9
B25: ARR needed to return 5.0x | C25: =(5*C7)/(C11*'Pricing Assumptions'!$C$16) -> 11515152
B27: For scale: the coordination-layer software market (production-mgmt incl. cost-tracking + collaboration) is ~$4.9B by 2030, growing ~9%/yr; the ARR above is ~0.1–0.3% of it. The broader category is proven — Magnific reached $230M ARR bootstrapped — but the serviceable target is the layer, not the generators.

Sheet Round & Investor Cap
B2: ANONA / TENET
B3: Round Construction — investor cap, minimum check, dilution at exit
B4: How many investors, how big each check, and what each stake is worth at exit after dilution ('watered-down'). Blue = inputs.
B6: ROUND INPUTS
B7: Target raise | C7: ='Pricing Assumptions'!$C$12 -> 3750000
B8: Post-money valuation | C8: ='Pricing Assumptions'!$C$13 -> 19000000
B9: Minimum investment (check) | C9: 250000
B10: Ownership retained to exit | C10: ='Pricing Assumptions'!$C$14 -> 0.55
B11: Exit ARR (base) | C11: ='Revenue Ramp'!$C$18 -> 5377500
B12: Exit valuation multiple (base) | C12: ='Pricing Assumptions'!$C$16 -> 15
B14: COMPUTED
B15: Seed ownership pool at close | C15: =C7/C8 -> 0.19736842
B16: Pool ownership at exit (after dilution) | C16: =C15*C10 -> 0.10855263
B17: Exit enterprise value (base) | C17: =C11*C12 -> 80662500
B18: Maximum number of investors (cap) | C18: =ROUNDDOWN(C7/C9,0) -> 15
B20: PER INVESTOR — at the minimum check
B21: Investment | C21: =C9 -> 250000
B22: Ownership at close | C22: =C21/C8 -> 0.013157895
B23: Ownership at exit (watered down) | C23: =C22*C10 -> 0.0072368421
B24: Stake value at exit (base) | C24: =C23*C17 -> 583741.78
B25: Gain at exit | C25: =C24-C21 -> 333741.78
B26: Return multiple (MOIC) | C26: =C24/C21 -> 2.3349671
B28: ROUND SHAPE — by minimum check (watered-down at exit)
B29: Min check | C29: Max investors | D29: Own % at close | E29: Own % at exit | F29: Stake at exit | G29: MOIC
B30: 500000 | C30: =ROUNDDOWN($C$7/B30,0) -> 7 | D30: =B30/$C$8 -> 0.026315789 | E30: =D30*$C$10 -> 0.014473684 | F30: =E30*$C$17 -> 1167483.6 | G30: =F30/B30 -> 2.3349671
B31: 250000 | C31: =ROUNDDOWN($C$7/B31,0) -> 15 | D31: =B31/$C$8 -> 0.013157895 | E31: =D31*$C$10 -> 0.0072368421 | F31: =E31*$C$17 -> 583741.78 | G31: =F31/B31 -> 2.3349671
B32: 150000 | C32: =ROUNDDOWN($C$7/B32,0) -> 25 | D32: =B32/$C$8 -> 0.0078947368 | E32: =D32*$C$10 -> 0.0043421053 | F32: =E32*$C$17 -> 350245.07 | G32: =F32/B32 -> 2.3349671
B33: 100000 | C33: =ROUNDDOWN($C$7/B33,0) -> 37 | D33: =B33/$C$8 -> 0.0052631579 | E33: =D33*$C$10 -> 0.0028947368 | F33: =E33*$C$17 -> 233496.71 | G33: =F33/B33 -> 2.3349671
B35: MOIC is identical across check sizes — the cap and minimum decide how many investors and how big each stake, not the return. Watering-down is the dilution from 'own % at close' to 'own % at exit'.
B36: AGGREGATE — does it clear the expected return?
B37: Total invested (the round) | C37: =C7 -> 3750000
B38: Total investor stake at exit (base) | C38: =C16*C17 -> 8756126.6
B39: If investors expect 3.0x, return 'owed' | C39: =3*C37 -> 11250000
B40: Base case covers the 3x expectation? | C40: =IF(C38>=C39,"YES — covered","Short by "&TEXT(C39-C38,"$#,##0")) -> Short by $2,493,873
B42: OWNERSHIP AT CLOSE — FULLY DILUTED
B43: Holder | C43: New capital | D43: Ownership
B44: Founders | C44: — | D44: =1-D45-D46 -> 0.70263158
B45: Option pool (unallocated) | C45: — | D45: 0.1
B46: New seed investors | C46: =C7 -> 3750000 | D46: =C15 -> 0.19736842
B47: — of which bridge note (converts in) | C47: 66000 | D47: =C47/C8 -> 0.0034736842
...

Sheet Valuation Basis
B2: ANONA / TENET
B3: Valuation Basis — defending a current valuation
B4: A seed valuation is negotiated, not calculated — but two independent methods bracket a defensible range. Blue = our choices; black = 2025 market data.
B6: METHOD A — COMPARABLE SEED ROUNDS (2025 market data)
B7: Median seed post-money valuation | C7: 20000000 | F7: Carta / SaaStr, 2025
B8: AI-software median seed post-money | C8: 19000000 | F8: Carta / FutureSight, 2025 — AI premium vs ~$15M market
B9: Seed post-money — 25th percentile | C9: 13800000 | F9: Carta, 2025
B10: Seed post-money — 95th percentile | C10: 80500000 | F10: Carta, 2025 — hot AI deals stretch the top
B11: Median seed cash raised | C11: 4000000 | F11: Carta, 2025 — our $3.75M is ~median
B12: Typical seed dilution | C12: 0.2 | F12: Carta, 2025 — founders sell ~20%
B13: → Post-money implied by our $3.75M at 20% dilution | C13: ='Pricing Assumptions'!$C$12/0.2 -> 18750000 | F13: raise ÷ standard dilution
B15: METHOD B — FORWARD CROSS-CHECK (Series A, backward)
B16: Projected ARR at Series A (~Month 18) | C16: ='Revenue Ramp'!$C$18 -> 5377500 | F16: from Revenue Ramp
B17: Median Series A post-money (SaaS, 2025) | C17: 50000000 | F17: Carta Q3 2025 — $45–60M range
B18: Median seed→Series A step-up | C18: 2.6 | F18: Carta, 2025
B19: → Implied seed post (Series A ÷ step-up) | C19: =C17/C18 -> 19230769
B21: DEFENSIBLE RANGE (post-money)
C22: Conservative | D22: Base | E22: Aggressive
B23: Post-money valuation | C23: 15000000 | D23: 19000000 | E23: 22000000
B24: Dilution at $3.75M raise | C24: ='Pricing Assumptions'!$C$12/C23 -> 0.25 | D24: ='Pricing Assumptions'!$C$12/D23 -> 0.19736842 | E24: ='Pricing Assumptions'!$C$12/E23 -> 0.17045455
B25: Conservative = investor-favorable (more dilution); Base ≈ AI-seed median at market-standard ~20% dilution; Aggressive = anchor + AI-native premium, still below the 95th percentile.
B27: WHAT IT MEANS FOR INVESTOR RETURN (base-case exit)
B28: Base-case exit enterprise value | C28: ='Revenue Ramp'!$C$18*'Pricing Assumptions'!$C$16 -> 80662500 | F28: exit ARR × base multiple
B29: Investor MOIC at base-case exit | C29: ='Pricing Assumptions'!$C$14*$C$28/C23 -> 2.957625 | D29: ='Pricing Assumptions'!$C$14*$C$28/D23 -> 2.3349671 | E29: ='Pricing Assumptions'!$C$14*$C$28/E23 -> 2.0165625
B30: The tension: a higher valuation means less dilution for you but a lower multiple for investors. At a market-standard ~$19M post, the base case returns ~2.3x; holding 3x+ at that valuation leans on the upside exit (higher ARR or multiple).
B32: RECOMMENDATION
B33: The data supports a $15M–$22M post-money. The model runs the base ~$19M (Pricing Assumptions C13) — the market-standard ~20% dilution and AI-seed median. To stress-test, switch C13 to the $15M conservative or $22M aggressive case and every return re-prices automatically.
B35: Negotiated, not computed. Market figures: Carta / SaaStr / FutureSight 2025. Not investment advice.

Sheet Benchmarks
B2: ANONA / TENET
B3: Comparable proof points — the category is real
B5: Metric | C5: Figure | D5: Source
B6: Magnific (formerly Freepik) ARR | C6: $230M | D6: Fortune / TNW, 2026 — ~$230M ARR, bootstrapped; ~half from video post-rebrand
B7: Magnific paying subscribers | C7: 1,000,000+ | D7: TNW, 2026
B8: Magnific enterprise customers | C8: 250+ | D8: incl. BBC, Puma, Carl's Jr, Delivery Hero, R/GA, Amazon Prime Video. TNW, 2026
B9: Magnific images generated / day | C9: 4,000,000+ | D9: TNW, 2026
B10: Magnific capital raised (VC) | C10: $0 (bootstrapped) | D10: TNW / Fortune, 2026
B11: Magnific model | C11: Model-agnostic orchestration layer | D11: dealflow.es, 2026 — aggregates 3rd-party AI models
B12: Magnific individual pricing | C12: ~$39/mo; ~$0.32/image credits | D12: pangea.app, Feb 2026
B13: ElevenLabs (valuation anchor) | C13: $11B on ~$500M ARR (~22x) | D13: TechCrunch / CNBC, Feb 2026 — prior model note ($430M/25x) now superseded
B14: ANONA wedge vs. Magnific | C14: JANE-anchored production vertical | D14: Magnific is image-first, expanding to video — ANONA's edge is the live anchor customer + workflow depth
B17: Wrapbook (sober valuation comp) | C17: $750M val; ~50% YoY growth | D17: Hollywood Reporter / Tracxn, 2024–26 — production payroll + real-time cost tracking; closest functional analog
B18: monday.com (orchestration, public) | C18: $351M Q1’26 rev (+24% YoY) | D18: Q1 2026 earnings — AI ~10% of net-new ARR; work-OS pressing into the layer from above
... B21: TENET base-case SOM | C21: ~$5.4M ARR (~0.1% of SAM) | D21: ANONA model, this workbook — a sliver of the software layer, not the $255B production economy
B23: Note: figures are from public reporting as of June 2026; private/forecast values are self-reported or estimated. ANONA revenue figures in this model are illustrative inputs to be validated. Comparable-company detail also lives in the Competitive Comparison workbook.
