Workbook

Sheet Summary
B2: ANONA / TENET
B3: Seed Round Investment Plan
B4: Prepared for investor + legal review | May 2026 | 12-month timeline revision, June 2026
B6: ROUND OVERVIEW
B7: Round | C7: Seed
B8: Target raise | C8: 3750000 | F8: Primary target
B9: Floor | C9: 3500000 | F9: Executes plan on a tighter ~11-mo runway
B10: Ceiling | C10: 4500000 | F10: Oversubscribed; deepens the Series A cushion (~15 mo)
B11: Runway target | C11: 12–14 months | F11: To the Series A raise (hard-locked)
B12: Instrument | C12: TBD — see Funding Mechanism tab | F12: Bridge vs. accelerated first close
B15: USE OF FUNDS — $3.75M TARGET | C15: Allocation | D15: % of Raise
B16: Engineering & infrastructure | C16: 1820000 | D16: =C16/$C$21
B17: Design & product | C17: 365000 | D17: =C17/$C$21
B18: Founder & operations | C18: 733000 | D18: =C18/$C$21
B19: Brand & strategy | C19: 375000 | D19: =C19/$C$21 | F19: Brand build + strategy; thesis post-close
B20: Reserves / contingency | C20: 457000 | D20: =C20/$C$21 | F20: ~12% buffer (incl. working capital) to Series A
B21: Total | C21: =SUM(C16:C20) | D21: =C21/$C$21
B25: IMMEDIATE CAPITAL ASK (BRIDGE — FIRST 90 DAYS)
B26: Roger Obando — fractional CTO retainer | C26: =14000*3 | F26: $14K/mo × 3 months (bridge window)
B27: Immediate operating costs (legal, setup, infra) | C27: 24000 | F27: Estimate — refine on call
B28: Immediate ask total | C28: =SUM(C26:C27) | F28: Bridge only: Roger + legal/setup. Operating plan funded by seed.

Sheet Use of Funds
B2: Use of Funds — Detail
B3: Line-item breakdown supporting the $3.75M allocation
B5: Category / line item | C5: Amount | D5: % of Raise | E5: Notes
B6: ENGINEERING & INFRASTRUCTURE
B7: Engineering Lead (senior, AI orchestration) | C7: 320000 | D7: =C7/$C$41 | E7: Top hire priority — fully loaded yr1
B8: Senior Frontend / Product Engineer (NLE-adjacent) | C8: 260000 | D8: =C8/$C$41 | E8: Loaded yr1
B9: Second engineer (from month 3) | C9: 200000 | D9: =C9/$C$41 | E9: Accelerated to month 3 to hit compressed schedule
B10: Cloud / GPU / model inference infra | C10: 460000 | D10: =C10/$C$41 | E10: Tighter capacity vs. $480K baseline
B11: Tooling, licenses, dev infrastructure | C11: 140000 | D11: =C11/$C$41
B12: Fractional CTO / eng-lead seat (4 mo + held) | C12: 70000 | D12: =C12/$C$41 | E12: Roger M1–4; hands off to full-time Eng Lead
B13: Engineering contingency | C13: 370000 | D13: =C13/$C$41 | E13: Within engineering envelope
B14: Subtotal | C14: =SUM(C7:C13) | D14: =C14/$C$41
B16: DESIGN & PRODUCT
B17: Product Designer (multi-state UI / motion) | C17: 250000 | D17: =C17/$C$41 | E17: M1–10; wraps post-V1 ship, shifts to iteration post-Series A
B18: Design tooling & prototyping | C18: 40000 | D18: =C18/$C$41
B19: Product validation (test sessions, instrumentation) | C19: 75000 | D19: =C19/$C$41 | E19: ANONA-run; JANE provides live jobs as anchor customer
B20: Subtotal | C20: =SUM(C17:C19) | D20: =C20/$C$41
B22: FOUNDER & OPERATIONS
B23: Founder compensation | C23: 360000 | D23: =C23/$C$41 | E23: $25K/mo M1–6, $30K/mo M7–12 (below market; equity offsets)
B24: Legal, accounting, corporate formation | C24: 70000 | D24: =C24/$C$41 | E24: Incl. round + ongoing counsel
B25: Producer / Operations (full-time, day 15) | C25: 225000 | D25: =C25/$C$41 | E25: $225K/yr loaded, full-time from day 15
B26: Office / operations / misc. | C26: 78000 | D26: =C26/$C$41
B27: Subtotal | C27: =SUM(C23:C26) | D27: =C27/$C$41
B29: BRAND & STRATEGY
B30: Strategy (positioning, GTM, advisory team) | C30: 260000 | D30: =C30/$C$41 | E30: M1–9 front-loaded to inform customer pilots
B31: Brand development (website, identity, system) | C31: 115000 | D31: =C31/$C$41 | E31: Site, logo, design system; M1–9, wraps before GTM
B32: Subtotal | C32: =SUM(C30:C31) | D32: =C32/$C$41
B34: RESERVES / CONTINGENCY
B35: Unallocated reserve + working capital | C35: 457000 | D35: =C35/$C$41 | E35: ~12% buffer (incl. working capital); helps extend Series A timeline
B36: Subtotal | C36: =SUM(C35:C35) | D36: =C36/$C$41
B41: TOTAL RAISE | C41: =C14+C20+C27+C32+C36 | D41: =C41/C41
B43: Salary figures are fully-loaded yr1 estimates (incl. benefits/taxes). Headcount per Section 7 hiring plan.

Sheet Funding Mechanism
B2: Funding Mechanism — Our Recommendation
B3: How we propose to fund the first 60–90 days while the full seed closes
C5: Option 1 — Bridge / Convertible Note | D5: Option 2 — Accelerated First Close
B6: What it is | C6: Short-term note covering immediate operating expenses; converts into the seed round at close. | D6: Pull a tranche of the seed forward to fund first 90 days; balance closes on normal timeline.
B7: Covers | C7: Covers Roger and immediate operating costs through close. | D7: Covers Roger plus first-90-day operations against the priced round.
B8: Speed to deploy | C8: Fast — note docs are lighter than full round close. | D8: Depends on first-close readiness; can be quick if leads are committed.
B9: Legal lift | C9: Lower upfront; note + cap/discount terms. | D9: Higher — requires priced/structured round docs sooner.
B10: Dilution clarity | C10: Deferred — converts later at cap/discount. | D10: Immediate — priced at close.
B11: Best when | C11: We use this to preserve momentum without locking full round terms before close. | D11: We use this when leads are ready to commit and prefer a single clean instrument.
B12: Why it fits here | C12: Fastest way to get the team operational and the build moving immediately. | D12: Cleanest cap-table outcome if the round prices on the near-term timeline.
B14: RECOMMENDED PATH
B15: We recommend a HYBRID: a short-term bridge note funds the first 90 days (Roger + legal/setup, ~$66K), then converts into the priced seed at the round close. This protects the start date without locking full round terms early. Note terms (cap, discount, conversion trigger) to be finalized with counsel — see below.
B17: BRIDGE SCOPE
B18: The bridge funds only Roger’s engagement (3 months) and legal/corporate setup (~$66K) during the 90-day window while the full seed closes. It does NOT fund the 12-month operating plan, team buildout, or infrastructure — those are funded by the seed itself.
B20: HYBRID TERMS (to finalize with counsel)
B21: Bridge amount | C21: ~$66K (Roger 3 mo + legal/setup)
B22: Instrument | C22: Convertible note — TBD
B23: Conversion cap / discount | C23: TBD with counsel
B24: Conversion trigger | C24: Close of priced seed — TBD
B25: Exclusivity / timeline | C25: TBD with counsel

Sheet Runway
B2: 12-Month Runway — Illustrative Burn
B3: Simplified monthly view. Hiring ramps per Section 7. Refine on weekend call.
B5: ($ per month) | C5: M1 | D5: M2 | E5: M3 | F5: M4 | G5: M5 | H5: M6 | I5: M7 | J5: M8 | K5: M9 | L5: M10 | M5: M11 | N5: M12
B6: Founder | C6: 30000 | D6: 30000 | E6: 30000 | F6: 30000 | G6: 30000 | H6: 30000 | I6: 30000 | J6: 30000 | K6: 30000 | L6: 30000 | M6: 30000 | N6: 30000
B7: Producer / Operations | C7: 18750 | D7: 18750 | E7: 18750 | F7: 18750 | G7: 18750 | H7: 18750 | I7: 18750 | J7: 18750 | K7: 18750 | L7: 18750 | M7: 18750 | N7: 18750
B8: Eng Lead | C8: 26667 | D8: 26667 | E8: 26667 | F8: 26667 | G8: 26667 | H8: 26667 | I8: 26667 | J8: 26667 | K8: 26667 | L8: 26667 | M8: 26667 | N8: 26667
B9: Sr Frontend Eng | C9: 21667 | D9: 21667 | E9: 21667 | F9: 21667 | G9: 21667 | H9: 21667 | I9: 21667 | J9: 21667 | K9: 21667 | L9: 21667 | M9: 21667 | N9: 21667
B10: Second Eng | C10: 0 | D10: 0 | E10: 20000 | F10: 20000 | G10: 20000 | H10: 20000 | I10: 20000 | J10: 20000 | K10: 20000 | L10: 20000 | M10: 20000 | N10: 20000
B11: Product design & validation | C11: 35000 | D11: 35000 | E11: 35000 | F11: 35000 | G11: 35000 | H11: 35000 | I11: 35000 | J11: 35000 | K11: 35000 | L11: 35000 | M11: 7500 | N11: 7500
B12: Fractional CTO seat (Roger M1–4, then held) | C12: 17500 | D12: 17500 | E12: 17500 | F12: 17500 | G12: 0 | H12: 0 | I12: 0 | J12: 0 | K12: 0 | L12: 0 | M12: 0 | N12: 0
B13: Infra / compute / tooling | C13: 50000 | D13: 50000 | E13: 50000 | F13: 50000 | G13: 50000 | H13: 50000 | I13: 50000 | J13: 50000 | K13: 50000 | L13: 50000 | M13: 50000 | N13: 50000
B14: Brand & strategy | C14: 41667 | D14: 41667 | E14: 41667 | F14: 41667 | G14: 41667 | H14: 41667 | I14: 41667 | J14: 41667 | K14: 41667 | L14: 0 | M14: 0 | N14: 0
B15: Contingency & reserve (deployed) | C15: 30000 | D15: 30000 | E15: 30000 | F15: 50000 | G15: 50000 | H15: 50000 | I15: 70000 | J15: 70000 | K15: 70000 | L15: 100000 | M15: 100000 | N15: 111000
B16: Legal / ops / misc | C16: 30000 | D16: 30000 | E16: 30000 | F16: 6500 | G16: 6500 | H16: 6500 | I16: 6500 | J16: 6500 | K16: 6500 | L16: 6500 | M16: 6500 | N16: 6500
B17: Monthly burn | C17: =SUM(C6:C16) | D17: =SUM(D6:D16) | E17: =SUM(E6:E16) | F17: =SUM(F6:F16) | G17: =SUM(G6:G16) | H17: =SUM(H6:H16) | I17: =SUM(I6:I16) | J17: =SUM(J6:J16) | ... N17: =SUM(N6:N16)
B18: Capital remaining | C18: =3750000-C17 | D18: =C18-D17 | E18: =D18-E17 | F18: =E18-F17 | G18: =F18-G17 | H18: =G18-H17 | I18: =H18-I17 | J18: =I18-J17 | K18: =J18-K17 | ... N18: =M18-N17
B21: Blue = input assumptions. Adjust monthly figures to model scenarios. Capital remaining stays positive across 12 months; Series A required at M12 by design.

Sheet Pricing Assumptions
B2: ANONA / TENET
B3: Revenue Assumptions — inputs in blue
B4: Edit the blue cells to model scenarios. Everything on Revenue Ramp & Return Math flows from here.
B6: PRICING | C6: Value | D6: Source / note
B7: Anchor / enterprise account ACV ($/month) | C7: 20000 | D7: INPUT — JANE-type studio contract. Verify vs. actual JANE terms.
B8: Self-serve seat price ($/month) | C8: 79 | D8: INPUT — priced as production-grade. Benchmark: Magnific (ex-Freepik) individual tiers, repriced 2026 post-rebrand (Business plan launched early 2026); $79 sits above entry self-serve. Source: Magnific/Fortune, 2026.
B9: Usage / credits uplift (% of subscription) | C9: 0.25 | D9: INPUT — add-on compute/credits, like Magnific's token model (~$0.32/image).
B11: RETURN ASSUMPTIONS
B12: Seed raise ($) | C12: 3750000 | D12: From Summary tab — target round.
B13: Post-money valuation ($) | C13: 19000000 | D13: INPUT — base case at market-standard ~20% dilution (AI-seed median, per Valuation Basis). Supported by four funded categories now entering the coordination layer (see Comparable Companies). $15M is the conservative downside.
B14: Ownership retained through dilution (%) | C14: 0.55 | D14: INPUT — fraction of seed stake kept after future rounds to exit.
B15: Valuation multiple — conservative (x ARR) | C15: 8 | D15: INPUT — low end for creative-AI / vertical SaaS.
B16: Valuation multiple — base (x ARR) | C16: 15 | D16: INPUT — mid-teens. Frontier-model comp ElevenLabs ~22x ($11B / ~$500M ARR, Feb 2026); soberer coordination-layer comp Wrapbook ~$750M val on ~50% growth. Our 15x sits between. Source: TechCrunch / Hollywood Reporter, 2026.
B17: Valuation multiple — upside (x ARR) | C17: 22 | D17: INPUT — high end for fast-growing creative-AI infra.

Sheet Revenue Ramp
B2: ANONA / TENET
B3: 12-Month Revenue Ramp — illustrative
B4: Enterprise/pilot-led, JANE-anchored. Per-customer early-adopter pricing (the $20K ACV on Pricing Assumptions is the enterprise / Series-A target). Gross burn links live to the Runway tab.
B6: ($ per month) | C6: M1 | D6: M2 | E6: M3 | F6: M4 | G6: M5 | H6: M6 | I6: M7 | J6: M8 | K6: M9 | L6: M10 | M6: M11 | N6: M12
B7: JANE (internal → platform) MRR | C7: 0 | D7: 0 | E7: 0 | F7: 0 | G7: 0 | H7: 0 | I7: 4000 | J7: 4000 | K7: 6000 | L7: 8000 | M7: 8000 | N7: 8000
B8: External 1 (pilot → platform) MRR | C8: 0 | D8: 0 | E8: 0 | F8: 0 | G8: 4000 | H8: 4000 | I8: 5000 | J8: 5000 | K8: 5000 | L8: 6000 | M8: 6000 | N8: 6000
B9: External 2 (pilot → platform) MRR | C9: 0 | D9: 0 | E9: 0 | F9: 0 | G9: 0 | H9: 4000 | I9: 4000 | J9: 5000 | K9: 5000 | L9: 6000 | M9: 6000 | N9: 6000
B10: External 3 (onboarding) MRR | C10: 0 | D10: 0 | E10: 0 | F10: 0 | G10: 0 | H10: 0 | I10: 0 | J10: 3000 | K10: 8000 | L10: 8000 | M10: 10000 | N10: 12000
B12: Total recurring MRR | C12: =SUM(C7:C10) | D12: =SUM(D7:D10) | E12: =SUM(E7:E10) | F12: =SUM(F7:F10) | G12: =SUM(G7:G10) | H12: =SUM(H7:H10) | I12: =SUM(I7:I10) | J12: =SUM(J7:J10) | ... N12: =SUM(N7:N10)
B13: Revenue (monthly) | C13: =C12 | D13: =D12 | E13: =E12 | F13: =F12 | G13: =G12 | H13: =H12 | I13: =I12 | J13: =J12 | ... N13: =N12
B14: Gross burn (Runway tab) | C14: =Runway!C17 | D14: =Runway!D17 | E14: =Runway!E17 | F14: =Runway!F17 | G14: =Runway!G17 | H14: =Runway!H17 | I14: =Runway!I17 | J14: =Runway!J17 | ... N14: =Runway!N17
B15: Net burn (burn − revenue) | C15: =C14-C13 | D15: =D14-D13 | E15: =E14-E13 | F15: =F14-F13 | G15: =G14-G13 | H15: =H14-H13 | I15: =I14-I13 | J15: =J14-J13 | ... N15: =N14-N13
B17: HEADLINE
B18: Series A basis ARR (forward) — base, drives valuation | C18: 5000000 | F18: Forward Series-A ARR; M12 run-rate at right
B19: M12 run-rate ARR (M12 MRR × 12) | C19: =N12*12 | F19: trailing run-rate exiting M12 (~$384K)
B20: Cumulative revenue (12 mo) | C20: =SUM(C13:N13)
B21: Total gross burn (12 mo) | C21: =SUM(C14:N14)
B22: First revenue month | C22: ="Month "&MATCH(TRUE,INDEX(C13:N13>0,0),0)

Sheet Return Math
B2: ANONA / TENET
B3: Return Math — what it takes to return your capital
B4: Think of it as a development pro forma: capital in → build the asset → asset has an exit value (ARR × multiple) → your return = stake value ÷ capital in.
B6: OWNERSHIP
B7: Seed raise | C7: ='Pricing Assumptions'!$C$12
B8: Post-money valuation | C8: ='Pricing Assumptions'!$C$13
B9: Seed ownership at close | C9: =C7/C8
B10: Ownership retained to exit | C10: ='Pricing Assumptions'!$C$14
B11: Effective ownership at exit | C11: =C9*C10
B14: INVESTOR RETURN (MOIC) — exit ARR × valuation multiple
C15: Conservative | D15: Base (Series A basis) | E15: Upside
B16: Exit ARR → | C16: 3000000 | D16: ='Revenue Ramp'!$C$18 | E16: 7500000 | F16: Multiple ↓
B17: Conservative multiple | C17: =C$16*$F17*$C$11/$C$7 | D17: =D$16*$F17*$C$11/$C$7 | E17: =E$16*$F17*$C$11/$C$7 | F17: ='Pricing Assumptions'!$C$15
B18: Base multiple | C18: =C$16*$F18*$C$11/$C$7 | D18: =D$16*$F18*$C$11/$C$7 | E18: =E$16*$F18*$C$11/$C$7 | F18: ='Pricing Assumptions'!$C$16
B19: Upside multiple | C19: =C$16*$F19*$C$11/$C$7 | D19: =D$16*$F19*$C$11/$C$7 | E19: =E$16*$F19*$C$11/$C$7 | F19: ='Pricing Assumptions'!$C$17
B22: WHAT ARR DO WE NEED — at base multiple
B23: ARR needed to return 1.0x (capital back) | C23: =(1*C7)/(C11*'Pricing Assumptions'!$C$16)
B24: ARR needed to return 3.0x | C24: =(3*C7)/(C11*'Pricing Assumptions'!$C$16)
B25: ARR needed to return 5.0x | C25: =(5*C7)/(C11*'Pricing Assumptions'!$C$16)
B27: For scale: the coordination-layer software market (production-mgmt incl. cost-tracking + collaboration) is ~$4.9B by 2030, growing ~9%/yr; the ARR above is ~0.1–0.3% of it. The broader category is proven — Magnific reached $230M ARR bootstrapped — but the serviceable target is the layer, not the generators.

Sheet Round & Investor Cap
B2: ANONA / TENET
B3: Round Construction — investor cap, minimum check, dilution at exit
B4: How many investors, how big each check, and what each stake is worth at exit after dilution ('watered-down'). Blue = inputs.
B6: ROUND INPUTS
B7: Target raise | C7: ='Pricing Assumptions'!$C$12
B8: Post-money valuation | C8: ='Pricing Assumptions'!$C$13
B9: Minimum investment (check) | C9: 250000
B10: Ownership retained to exit | C10: ='Pricing Assumptions'!$C$14
B11: Exit ARR (base) | C11: ='Revenue Ramp'!$C$18
B12: Exit valuation multiple (base) | C12: ='Pricing Assumptions'!$C$16
B14: COMPUTED
B15: Seed ownership pool at close | C15: =C7/C8
B16: Pool ownership at exit (after dilution) | C16: =C15*C10
B17: Exit enterprise value (base) | C17: =C11*C12
B18: Maximum number of investors (cap) | C18: =ROUNDDOWN(C7/C9,0)
B20: PER INVESTOR — at the minimum check
B21: Investment | C21: =C9
B22: Ownership at close | C22: =C21/C8
B23: Ownership at exit (watered down) | C23: =C22*C10
B24: Stake value at exit (base) | C24: =C23*C17
B25: Gain at exit | C25: =C24-C21
B26: Return multiple (MOIC) | C26: =C24/C21
B28: ROUND SHAPE — by minimum check (watered-down at exit)
B29: Min check | C29: Max investors | D29: Own % at close | E29: Own % at exit | F29: Stake at exit | G29: MOIC
B30: 500000 | C30: =ROUNDDOWN($C$7/B30,0) | D30: =B30/$C$8 | E30: =D30*$C$10 | F30: =E30*$C$17 | G30: =F30/B30
B31: 250000 | C31: =ROUNDDOWN($C$7/B31,0) | D31: =B31/$C$8 | E31: =D31*$C$10 | F31: =E31*$C$17 | G31: =F31/B31
B32: 150000 | C32: =ROUNDDOWN($C$7/B32,0) | D32: =B32/$C$8 | E32: =D32*$C$10 | F32: =E32*$C$17 | G32: =F32/B32
B33: 100000 | C33: =ROUNDDOWN($C$7/B33,0) | D33: =B33/$C$8 | E33: =D33*$C$10 | F33: =E33*$C$17 | G33: =F33/B33
B35: MOIC is identical across check sizes — the cap and minimum decide how many investors and how big each stake, not the return. Watering-down is the dilution from 'own % at close' to 'own % at exit'.
B36: AGGREGATE — does it clear the expected return?
B37: Total invested (the round) | C37: =C7
B38: Total investor stake at exit (base) | C38: =C16*C17
B39: If investors expect 3.0x, return 'owed' | C39: =3*C37
B40: Base case covers the 3x expectation? | C40: =IF(C38>=C39,"YES — covered","Short by "&TEXT(C39-C38,"$#,##0"))
B42: OWNERSHIP AT CLOSE — FULLY DILUTED
B43: Holder | C43: New capital | D43: Ownership
B44: Founders | C44: — | D44: =1-D45-D46
B45: Option pool (unallocated) | C45: — | D45: 0.1
B46: New seed investors | C46: =C7 | D46: =C15
B47: — of which bridge note (converts in) | C47: 66000 | D47: =C47/C8
...

Sheet Valuation Basis
B2: ANONA / TENET
B3: Valuation Basis — defending a current valuation
B4: A seed valuation is negotiated, not calculated — but two independent methods bracket a defensible range. Blue = our choices; black = 2025 market data.
B6: METHOD A — COMPARABLE SEED ROUNDS (2025 market data)
B7: Median seed post-money valuation | C7: 20000000 | F7: Carta / SaaStr, 2025
B8: AI-software median seed post-money | C8: 19000000 | F8: Carta / FutureSight, 2025 — AI premium vs ~$15M market
B9: Seed post-money — 25th percentile | C9: 13800000 | F9: Carta, 2025
B10: Seed post-money — 95th percentile | C10: 80500000 | F10: Carta, 2025 — hot AI deals stretch the top
B11: Median seed cash raised | C11: 4000000 | F11: Carta, 2025 — our $3.75M is ~median
B12: Typical seed dilution | C12: 0.2 | F12: Carta, 2025 — founders sell ~20%
B13: → Post-money implied by our $3.75M at 20% dilution | C13: ='Pricing Assumptions'!$C$12/0.2 | F13: raise ÷ standard dilution
B15: METHOD B — FORWARD CROSS-CHECK (Series A, backward)
B16: Projected ARR at Series A (~Month 12–14) | C16: ='Revenue Ramp'!$C$18 | F16: from Revenue Ramp
B17: Median Series A post-money (SaaS, 2025) | C17: 50000000 | F17: Carta Q3 2025 — $45–60M range
B18: Median seed→Series A step-up | C18: 2.6 | F18: Carta, 2025
B19: → Implied seed post (Series A ÷ step-up) | C19: =C17/C18
B21: DEFENSIBLE RANGE (post-money)
C22: Conservative | D22: Base | E22: Aggressive
B23: Post-money valuation | C23: 15000000 | D23: 19000000 | E23: 22000000
B24: Dilution at $3.75M raise | C24: ='Pricing Assumptions'!$C$12/C23 | D24: ='Pricing Assumptions'!$C$12/D23 | E24: ='Pricing Assumptions'!$C$12/E23
B25: Conservative = investor-favorable (more dilution); Base ≈ AI-seed median at market-standard ~20% dilution; Aggressive = anchor + AI-native premium, still below the 95th percentile.
B27: WHAT IT MEANS FOR INVESTOR RETURN (base-case exit)
B28: Base-case exit enterprise value | C28: ='Revenue Ramp'!$C$18*'Pricing Assumptions'!$C$16 | F28: exit ARR × base multiple
B29: Investor MOIC at base-case exit | C29: ='Pricing Assumptions'!$C$14*$C$28/C23 | D29: ='Pricing Assumptions'!$C$14*$C$28/D23 | E29: ='Pricing Assumptions'!$C$14*$C$28/E23
B30: The tension: a higher valuation means less dilution for you but a lower multiple for investors. At a market-standard ~$19M post, the base case returns ~2.2x; holding 3x+ at that valuation leans on the upside exit (higher ARR or multiple).
B32: RECOMMENDATION
B33: The data supports a $15M–$22M post-money. The model runs the base ~$19M (Pricing Assumptions C13) — the market-standard ~20% dilution and AI-seed median. To stress-test, switch C13 to the $15M conservative or $22M aggressive case and every return re-prices automatically.
B35: Negotiated, not computed. Market figures: Carta / SaaStr / FutureSight 2025. Not investment advice.

Sheet Benchmarks
B2: ANONA / TENET
B3: Comparable proof points — the category is real
B5: Metric | C5: Figure | D5: Source
B6: Magnific (formerly Freepik) ARR | C6: $230M | D6: Fortune / TNW, 2026 — ~$230M ARR, bootstrapped; ~half from video post-rebrand
B7: Magnific paying subscribers | C7: 1,000,000+ | D7: TNW, 2026
B8: Magnific enterprise customers | C8: 250+ | D8: incl. BBC, Puma, Carl's Jr, Delivery Hero, R/GA, Amazon Prime Video. TNW, 2026
B9: Magnific images generated / day | C9: 4,000,000+ | D9: TNW, 2026
B10: Magnific capital raised (VC) | C10: $0 (bootstrapped) | D10: TNW / Fortune, 2026
B11: Magnific model | C11: Model-agnostic orchestration layer | D11: dealflow.es, 2026 — aggregates 3rd-party AI models
B12: Magnific individual pricing | C12: ~$39/mo; ~$0.32/image credits | D12: pangea.app, Feb 2026
B13: ElevenLabs (valuation anchor) | C13: $11B on ~$500M ARR (~22x) | D13: TechCrunch / CNBC, Feb 2026 — prior model note ($430M/25x) now superseded
B14: ANONA wedge vs. Magnific | C14: JANE-anchored production vertical | D14: Magnific is image-first, expanding to video — ANONA's edge is the live anchor customer + workflow depth
B17: Wrapbook (sober valuation comp) | C17: $750M val; ~50% YoY growth | D17: Hollywood Reporter / Tracxn, 2024–26 — production payroll + real-time cost tracking; closest functional analog
B18: monday.com (orchestration, public) | C18: $351M Q1’26 rev (+24% YoY) | D18: Q1 2026 earnings — AI ~10% of net-new ARR; work-OS pressing into the layer from above
... B21: TENET base-case SOM | C21: ~$5.0M ARR (~0.1% of SAM) | D21: ANONA model, this workbook — a sliver of the software layer, not the $255B production economy
B23: Note: figures are from public reporting as of June 2026; private/forecast values are self-reported or estimated. ANONA revenue figures in this model are illustrative inputs to be validated. Comparable-company detail also lives in the Competitive Comparison workbook.
